Workbook

Sheet Tracker
B2: FISI Job Search Tracker — Application Funnel
B3: seeded 2026-10-15 from download/jobs_latest.csv (2026-10-14 15:05 run) · followup_due = applied_date + 7 d · statuses per research/3-a A1
B4: id | C4: company | D4: role | E4: city | F4: source | G4: transit | H4: first_seen | I4: status | J4: applied_date | K4: followup_due | L4: fit | M4: url | N4: notes
B5: f4b5513939 | C5: PAMEC PAPP GmbH | D5: Mitarbeiter (gn) 1st Level Support | E5: Nürnberg, Mittelfranken | F5: BA | G5: 0-xfer (14min) | H5: 46309 | I5: discovered | K5: =IF(AND($J5<>"",$I5="applied"),$J5+7,"") | M5: https://www.arbeitsagentur.de/jobsuche/jobdetail/12310-2AYAV2GGEML8HP4M-S
B6: 059fc826c0 | C6: BAVARIAHEADHUNTER Schlegel & Wegner GbR | D6: Fachinformatiker Systemintegration (m/w/d) - ID 7285 | E6: Erlangen | F6: Kimeta | G6: 0-xfer (0min) | H6: 46309 | I6: discovered | K6: =IF(AND($J6<>"",$I6="applied"),$J6+7,"") | M6: https://www.kimeta.de/display-job/bavariaheadhunter-schlegel-wegner/fachinformatiker-systemintegration-m-w-d-id-7285/972430612.html
B7: 1beda5a947 | D7: Fachinformatiker Systemintegration (m/w/d) | E7: Nürnberg | F7: Kimeta | G7: 0-xfer (14min) | H7: 46309 | I7: discovered | K7: =IF(AND($J7<>"",$I7="applied"),$J7+7,"") | M7: https://www.kimeta.de/display-job/fachinformatiker-systemintegration-m-w-d/975620364.html
B8: 695a018f80 | C8: Hahn GmbH | D8: Technischer Kundenbetreuer - Fachinformatiker für Systemintegration (m/w) | E8: 90571 Schwaig bei Nürnberg | F8: Kimeta | G8: 0-xfer (14min) | H8: 46309 | I8: discovered | K8: =IF(AND($J8<>"",$I8="applied"),$J8+7,"") | M8: https://www.kimeta.de/display-job/hahn-immobilien-beteiligungs-ag/technischer-kundenbetreuer-fachinformatiker-fuer-systemintegration-m-w/965192470.html
B9: 42d8e64cf5 | C9: puro Personaldienstleistung GmbH | D9: Servicetechniker (m/w/d) IT Support und Kundenservice | E9: Hallstadt | F9: BA | G9: 0-xfer (30min) | H9: 46308 | I9: discovered | K9: =IF(AND($J9<>"",$I9="applied"),$J9+7,"") | M9: https://www.arbeitsagentur.de/jobsuche/jobdetail/13669-TT4FUBLV8JWAZIVD-S
B10: 1a4d2b7854 | C10: Minderleinsmühle GmbH & Co. KG Andreas Hubmann | D10: IT-Spezialist KI & Digitalisierung (m/w/d) | E10: Neunkirchen am Brand | F10: BA | G10: none | H10: 46308 | I10: discovered | K10: =IF(AND($J10<>"",$I10="applied"),$J10+7,"") | M10: https://www.arbeitsagentur.de/jobsuche/jobdetail/10000-1208271879-S
B11: 537fda9e37 | C11: set - software engineering gmbh | D11: DevOps Platform Engineer OpenShift (m/w/d) | E11: Nürnberg, Mittelfranken | F11: BA | G11: 0-xfer (14min) | H11: 46308 | I11: discovered | K11: =IF(AND($J11<>"",$I11="applied"),$J11+7,"") | M11: https://www.arbeitsagentur.de/jobsuche/jobdetail/10001-1003848227-S
B12: a6b4d86a08 | C12: cns computer & netzwerk service gmbh | D12: Fachinformatiker Systemintegration (m/w/d) | E12: Fürth, Bayern | F12: BA | G12: 0-xfer (7min) | H12: 46307 | I12: discovered | K12: =IF(AND($J12<>"",$I12="applied"),$J12+7,"") | M12: https://www.arbeitsagentur.de/jobsuche/jobdetail/10000-1208259481-S
B13: e55799d80d | C13: cns computer & netzwerk service gmbh | D13: IT-Systemadministrator (m/w/d) | E13: Fürth, Bayern | F13: BA | G13: 0-xfer (7min) | H13: 46307 | I13: discovered | K13: =IF(AND($J13<>"",$I13="applied"),$J13+7,"") | M13: https://www.arbeitsagentur.de/jobsuche/jobdetail/10000-1208259068-S
B14: 2ec5f77c7e | C14: H&P Höhnen & Partner | D14: IT-Administrator (m/w/d) | E14: Bamberg | F14: InFranken | G14: 0-xfer (20min) | H14: 46307 | I14: discovered | K14: =IF(AND($J14<>"",$I14="applied"),$J14+7,"") | M14: https://jobs.infranken.de/jobs/16416872/IT_Administrator_(m_w_d)_Bamberg_HundP_H%C3%B6hnen_und
B15: bf37cadfac | C15: Helmi Göttler Private Arbeitsvermittlung | D15: IT-Administrator (m/w/d) | E15: Erlangen | F15: Talent.com+XING | G15: 0-xfer (0min) | H15: 46306 | I15: discovered | K15: =IF(AND($J15<>"",$I15="applied"),$J15+7,"") | M15: https://www.xing.com/jobs/erlangen-it-administrator-158493371
B16: fdc6559c76 | C16: ncsolution GmbH | D16: Fachinformatiker Systemintegration (m/w/d) | E16: Erlangen | F16: BA | G16: 0-xfer (0min) | H16: 46304 | I16: discovered | K16: =IF(AND($J16<>"",$I16="applied"),$J16+7,"") | M16: https://www.arbeitsagentur.de/jobsuche/jobdetail/10001-1003832993-S
B17: 5ff196192c | C17: ANG GmbH | D17: Systemadministrator (m/w/d) | E17: Erlangen | F17: BA | G17: 0-xfer (0min) | H17: 46304 | I17: discovered | K17: =IF(AND($J17<>"",$I17="applied"),$J17+7,"") | M17: https://www.arbeitsagentur.de/jobsuche/jobdetail/10001-1003834249-S
B18: 373961e79c | C18: Neumüller Personalberatung Regina Neumüller e.K. | D18: Junior IT- System Administrator (m/w/d) | E18: Nürnberg, Mittelfranken | F18: BA | G18: 0-xfer (14min) | H18: 46304 | I18: discovered | K18: =IF(AND($J18<>"",$I18="applied"),$J18+7,"") | M18: https://www.arbeitsagentur.de/jobsuche/jobdetail/10001-1003830628-S
B19: c2d696535e | C19: NConsult GmbH | D19: Mitarbeiter IT-Support | Administration | Projekte (m/w/d) | E19: Nürnberg, Mittelfranken | F19: BA | G19: 0-xfer (14min) | H19: 46304 | I19: discovered | K19: =IF(AND($J19<>"",$I19="applied"),$J19+7,"") | M19: https://www.arbeitsagentur.de/jobsuche/jobdetail/10001-1003830762-S
B20: 9c281e389a | C20: NConsult GmbH | D20: 1st Level Supporter (m/w/d) | E20: Bamberg | F20: BA | G20: 0-xfer (20min) | H20: 46304 | I20: discovered | K20: =IF(AND($J20<>"",$I20="applied"),$J20+7,"") | M20: https://www.arbeitsagentur.de/jobsuche/jobdetail/10001-1003830672-S
B21: 2a9ca85e56 | C21: Neumüller Personalberatung Regina Neumüller e.K. | D21: IT Specialist (m/w/d) - Clientmanagement | E21: Röthenbach an der Pegnitz | F21: BA | H21: 46304 | I21: discovered | K21: =IF(AND($J21<>"",$I21="applied"),$J21+7,"") | M21: https://www.arbeitsagentur.de/jobsuche/jobdetail/10001-1003831106-S
B22: 7f2a603704 | C22: NConsult GmbH | D22: Linux Administrator (m/w/d) | E22: Nürnberg, Mittelfranken | F22: BA | G22: 0-xfer (14min) | H22: 46304 | I22: discovered | K22: =IF(AND($J22<>"",$I22="applied"),$J22+7,"") | M22: https://www.arbeitsagentur.de/jobsuche/jobdetail/10001-1003830208-S
B23: 56e3b57726 | C23: Akkodis Germany Tech Experts GmbH | D23: IT-Systemadministrator (m/w/d) | E23: Nürnberg, Mittelfranken | F23: BA | G23: 0-xfer (14min) | H23: 46304 | I23: discovered | K23: =IF(AND($J23<>"",$I23="applied"),$J23+7,"") | M23: https://www.arbeitsagentur.de/jobsuche/jobdetail/12634-BB-646012-7878-6530-S
B24: 0859e1138d | C24: BFI Informationssysteme GmbH | D24: IT Support Mitarbeiter (m/w/d) Netzwerktechnik | E24: Nürnberg, Mittelfranken | F24: BA | G24: 0-xfer (14min) | H24: 46303 | I24: discovered | K24: =IF(AND($J24<>"",$I24="applied"),$J24+7,"") | M24: https://www.arbeitsagentur.de/jobsuche/jobdetail/15297-0ahr6g81-S
B25: f29a7dd34d | C25: Suspa GmbH Betriebsstätte Altdorf | D25: Systemadministrator Netzwerk & Security | E25: Altdorf bei Nürnberg | F25: BA | G25: 1-xfer | H25: 46302 | I25: discovered | K25: =IF(AND($J25<>"",$I25="applied"),$J25+7,"") | M25: https://www.arbeitsagentur.de/jobsuche/jobdetail/10001-1003820240-S
B26: 15bef6b60a | C26: BFI Informationssysteme GmbH | D26: IT-Service Desk Mitarbeiter (m/w/d) - Referenznummer: 061026-3-NBG | E26: Nürnberg, Mittelfranken | F26: BA | G26: 0-xfer (14min) | H26: 46301 | I26: discovered | K26: =IF(AND($J26<>"",$I26="applied"),$J26+7,"") | M26: https://www.arbeitsagentur.de/jobsuche/jobdetail/15297-2u0wf5wb-S
B27: 84310fbf83 | C27: Akkodis Germany Tech Experts GmbH | D27: IT System Engineer (m/w/d) z/OS Netzwerk und Security | E27: Nürnberg, Mittelfranken | F27: BA | G27: 0-xfer (14min) | H27: 46301 | I27: discovered | K27: =IF(AND($J27<>"",$I27="applied"),$J27+7,"") | M27: https://www.arbeitsagentur.de/jobsuche/jobdetail/12634-BB-645864-7878-8663-S
B28: ef920652df | C28: puro Personaldienstleistung GmbH | D28: Fachinformatiker Systemintegration (m/w/d) | E28: Neumarkt in der Oberpfalz | F28: BA | G28: 1-xfer | H28: 46299 | I28: discovered | K28: =IF(AND($J28<>"",$I28="applied"),$J28+7,"") | M28: https://www.arbeitsagentur.de/jobsuche/jobdetail/13669-B4QJPZOZC7TLDT27-S
B29: 804639fcaa | C29: Brunel GmbH NL Mannheim | D29: IT-Spezialist (w/m/d) | E29: Erlangen | F29: BA+XING | G29: 0-xfer (0min) | H29: 46299 | I29: discovered | K29: =IF(AND($J29<>"",$I29="applied"),$J29+7,"") | M29: https://www.arbeitsagentur.de/jobsuche/jobdetail/12362-TR-300879_624701LS-S
B30: fbb754a462 | C30: FERCHAU GmbH Niederlassung Nürnberg City | D30: IT-Spezialist Netzwerk & Connectivity (m/w/d) | E30: Erlangen | F30: BA | G30: 0-xfer (0min) | H30: 46297 | I30: discovered | K30: =IF(AND($J30<>"",$I30="applied"),$J30+7,"") | M30: https://www.arbeitsagentur.de/jobsuche/jobdetail/12265-516301_JB5262829-S
B31: c47162e723 | C31: SIMBA DICKIE GROUP GMBH | D31: (Junior) IT Manager First Level Support (m/w/d) | E31: Fürth | F31: Indeed | G31: 0-xfer (7min) | H31: 46297 | I31: discovered | K31: =IF(AND($J31<>"",$I31="applied"),$J31+7,"") | M31: https://de.indeed.com/viewjob?jk=2fc62b848db1054e
B32: 77afdb7c13 | C32: HEGMANNS Gruppe | D32: IT-Systemadministrator (m/w/d) | E32: Nürnberg | F32: Indeed | G32: 0-xfer (14min) | H32: 46297 | I32: discovered | K32: =IF(AND($J32<>"",$I32="applied"),$J32+7,"") | M32: https://de.indeed.com/viewjob?jk=b784cbebc0c60fd4
B33: a11270084c | C33: Akkodis Germany Tech Experts GmbH | D33: System Engineer (m/w/d) Linux | E33: Nürnberg, Mittelfranken | F33: BA | G33: 0-xfer (14min) | H33: 46296 | I33: discovered | K33: =IF(AND($J33<>"",$I33="applied"),$J33+7,"") | M33: https://www.arbeitsagentur.de/jobsuche/jobdetail/12634-BB-645665-7878-7513-S
... B35: 3f94e6736b | C35: Akkodis Germany Tech Experts GmbH | D35: System Engineer Netzwerk (m/w/d) | E35: Nürnberg, Mittelfranken | F35: BA | G35: 0-xfer (14min) | H35: 46296 | I35: discovered | K35: =IF(AND($J35<>"",$I35="applied"),$J35+7,"") | M35: https://www.arbeitsagentur.de/jobsuche/jobdetail/12634-BB-645661-7878-3965-S
B36: 78882b114a | C36: FERCHAU GmbH Niederlassung Nürnberg City | D36: Systemmanager (m/w/d) für Linux Netzwerkinfrastruktur | E36: Röthenbach an der Pegnitz | F36: BA | H36: 46295 | I36: discovered | K36: =IF(AND($J36<>"",$I36="applied"),$J36+7,"") | M36: https://www.arbeitsagentur.de/jobsuche/jobdetail/12265-522292_JB5259677-S
B37: ebb04d69a4 | C37: Akkodis Germany Tech Experts GmbH | D37: Professional System Engineer / IT System Administrator Test- & Plattformbetrieb (m/w/d) | E37: Nürnberg, Mittelfranken | F37: BA | G37: 0-xfer (14min) | H37: 46295 | I37: discovered | K37: =IF(AND($J37<>"",$I37="applied"),$J37+7,"") | M37: https://www.arbeitsagentur.de/jobsuche/jobdetail/12634-BB-645620-7878-4652-S
B38: 1bca89b8a9 | C38: i k hofmann | D38: Elektroniker - Systemintegration (m/w/d) | E38: Erlangen | F38: Talent.com | G38: 0-xfer (0min) | I38: discovered | K38: =IF(AND($J38<>"",$I38="applied"),$J38+7,"") | M38: https://de.talent.com/view?id=534434325413693414
B39: ed73692695 | C39: Capgemini | D39: DevOps Engineer (w/m/d) | F39: Get-in-IT | I39: discovered | K39: =IF(AND($J39<>"",$I39="applied"),$J39+7,"") | M39: https://www.get-in-it.de/jobsuche/p311769
B40: 59a93a8a71 | C40: pace-IT GmbH | D40: IT-Systemadministrator (m/w/d) | F40: Get-in-IT | I40: discovered | K40: =IF(AND($J40<>"",$I40="applied"),$J40+7,"") | M40: https://www.get-in-it.de/jobsuche/p313176
B41: b3943614e9 | C41: DMG MORI Digital GmbH | D41: IT-Systemadministrator (m/w/d) - Azure & IT Operations | F41: Get-in-IT | I41: discovered | K41: =IF(AND($J41<>"",$I41="applied"),$J41+7,"") | M41: https://www.get-in-it.de/jobsuche/p313154
B42: 5031965d1a | C42: Johanniter-Unfall-Hilfe e.V. | D42: IT-Administrator (m/w/d) | F42: Get-in-IT | I42: discovered | K42: =IF(AND($J42<>"",$I42="applied"),$J42+7,"") | M42: https://www.get-in-it.de/jobsuche/p313305
...

Sheet Funnel
B2: Funnel Metrics — Friday Review
B3: live formulas over the Tracker sheet · research/3-a A5: review weekly, shift effort toward what produces interviews
B4: metric | C4: value | E4: target / reading
B5: postings in tracker | C5: =COUNTA(Tracker!$B$5:$B$50) -> 46 | E5: top of funnel = pipeline input
B6: discovered (unreviewed) | C6: =COUNTIF(Tracker!$I$5:$I$50,"discovered") -> 46 | E6: review these Friday → shortlist or close
B7: shortlisted | C7: =COUNTIF(Tracker!$I$5:$I$50,"shortlisted") -> 0 | E7: tailoring budget goes here (3–5 h/app in DE)
B8: applied | C8: =COUNTIF(Tracker!$I$5:$I$50,"applied") -> 0
B9: interviewing | C9: =COUNTIF(Tracker!$I$5:$I$50,"interviewing") -> 0
B10: offer | C10: =COUNTIF(Tracker!$I$5:$I$50,"offer") -> 0
B11: closed / rejected | C11: =COUNTIF(Tracker!$I$5:$I$50,"closed")+COUNTIF(Tracker!$I$5:$I$50,"rejected") -> 0 | E11: keep for conversion math
B12: follow-ups OVERDUE | C12: =SUMPRODUCT((Tracker!$I$5:$I$50="applied")*(Tracker!$K$5:$K$50<>"")*(Tracker!$K$5:$K$50<TODAY())) -> 0 | E12: 0 = on-cadence (5–7 d rule)
B13: conversion: applied→interview+ | C13: =IFERROR((COUNTIF(Tracker!$I$5:$I$50,"interviewing")+COUNTIF(Tracker!$I$5:$I$50,"offer"))/COUNTIF(Tracker!$I$5:$I$50,"applied"),0) -> 0 | E13: benchmark ~12% (4 of 32); below → fix resume/top-of-funnel
B14: conversion: interview+→offer | C14: =IFERROR(COUNTIF(Tracker!$I$5:$I$50,"offer")/(COUNTIF(Tracker!$I$5:$I$50,"interviewing")+COUNTIF(Tracker!$I$5:$I$50,"offer")),0) -> 0 | E14: below ~20% → practice interviews, not more applications
B16: source | C16: rows | D16: active | E16: shortlisted
B17: BA | C17: =COUNTIF(Tracker!$F$5:$F$50,"BA") -> 25 | D17: =SUMPRODUCT((Tracker!$F$5:$F$50="BA")*(Tracker!$I$5:$I$50<>"discovered")*(Tracker!$I$5:$I$50<>"closed")*(Tracker!$I$5:$I$50<>"rejected")) -> 0 | E17: =SUMPRODUCT((Tracker!$F$5:$F$50="BA")*(Tracker!$I$5:$I$50="shortlisted")) -> 0
B18: BA+XING | C18: =COUNTIF(Tracker!$F$5:$F$50,"BA+XING") -> 1 | D18: =SUMPRODUCT((Tracker!$F$5:$F$50="BA+XING")*(Tracker!$I$5:$I$50<>"discovered")*(Tracker!$I$5:$I$50<>"closed")*(Tracker!$I$5:$I$50<>"rejected")) -> 0 | E18: =SUMPRODUCT((Tracker!$F$5:$F$50="BA+XING")*(Tracker!$I$5:$I$50="shortlisted")) -> 0
B19: Get-in-IT | C19: =COUNTIF(Tracker!$F$5:$F$50,"Get-in-IT") -> 5 | D19: =SUMPRODUCT((Tracker!$F$5:$F$50="Get-in-IT")*(Tracker!$I$5:$I$50<>"discovered")*(Tracker!$I$5:$I$50<>"closed")*(Tracker!$I$5:$I$50<>"rejected")) -> 0 | E19: =SUMPRODUCT((Tracker!$F$5:$F$50="Get-in-IT")*(Tracker!$I$5:$I$50="shortlisted")) -> 0
B20: InFranken | C20: =COUNTIF(Tracker!$F$5:$F$50,"InFranken") -> 1 | D20: =SUMPRODUCT((Tracker!$F$5:$F$50="InFranken")*(Tracker!$I$5:$I$50<>"discovered")*(Tracker!$I$5:$I$50<>"closed")*(Tracker!$I$5:$I$50<>"rejected")) -> 0 | E20: =SUMPRODUCT((Tracker!$F$5:$F$50="InFranken")*(Tracker!$I$5:$I$50="shortlisted")) -> 0
B21: Indeed | C21: =COUNTIF(Tracker!$F$5:$F$50,"Indeed") -> 2 | D21: =SUMPRODUCT((Tracker!$F$5:$F$50="Indeed")*(Tracker!$I$5:$I$50<>"discovered")*(Tracker!$I$5:$I$50<>"closed")*(Tracker!$I$5:$I$50<>"rejected")) -> 0 | E21: =SUMPRODUCT((Tracker!$F$5:$F$50="Indeed")*(Tracker!$I$5:$I$50="shortlisted")) -> 0
B22: Kimeta | C22: =COUNTIF(Tracker!$F$5:$F$50,"Kimeta") -> 3 | D22: =SUMPRODUCT((Tracker!$F$5:$F$50="Kimeta")*(Tracker!$I$5:$I$50<>"discovered")*(Tracker!$I$5:$I$50<>"closed")*(Tracker!$I$5:$I$50<>"rejected")) -> 0 | E22: =SUMPRODUCT((Tracker!$F$5:$F$50="Kimeta")*(Tracker!$I$5:$I$50="shortlisted")) -> 0
B23: Talent.com | C23: =COUNTIF(Tracker!$F$5:$F$50,"Talent.com") -> 8 | D23: =SUMPRODUCT((Tracker!$F$5:$F$50="Talent.com")*(Tracker!$I$5:$I$50<>"discovered")*(Tracker!$I$5:$I$50<>"closed")*(Tracker!$I$5:$I$50<>"rejected")) -> 0 | E23: =SUMPRODUCT((Tracker!$F$5:$F$50="Talent.com")*(Tracker!$I$5:$I$50="shortlisted")) -> 0
B24: Talent.com+XING | C24: =COUNTIF(Tracker!$F$5:$F$50,"Talent.com+XING") -> 1 | D24: =SUMPRODUCT((Tracker!$F$5:$F$50="Talent.com+XING")*(Tracker!$I$5:$I$50<>"discovered")*(Tracker!$I$5:$I$50<>"closed")*(Tracker!$I$5:$I$50<>"rejected")) -> 0 | E24: =SUMPRODUCT((Tracker!$F$5:$F$50="Talent.com+XING")*(Tracker!$I$5:$I$50="shortlisted")) -> 0
B26: source yield: keep feeding sources with high active/rows ratio; demote sources that never produce shortlisted rows (research/3-a B5)

Sheet Playbook
B2: Playbook — How to Run This File
B3: methodology from research/3-a (Cruit funnel, eztrackr columns, St. Louis Fed timing, Indeed/Muse follow-up cadence)
B4: Statuses (the MVP column — update it, everything else computes itself)
B5: • discovered — pulled by the pipeline, not reviewed yet
B6: • shortlisted — worth tailoring a real application (the 3–5 h budget goes here)
B7: • applied — sent; followup_due auto-fills +7 days (5–7 business-day rule)
B8: • interviewing — any human contact; log notes + contact name
B9: • offer — negotiate; everything before this was cost
B10: • closed — you withdrew or the role died; rejected — they said no. Keep both for funnel math.
B12: The weekly loop (Friday, 10 minutes)
B13: • 1. Funnel sheet: check follow-ups OVERDUE = 0, send any overdue follow-ups
B14: • 2. Review every 'discovered' row: shortlist or close — never leave them piling up
... B30: • daily pipeline CSVs in download/daily/ are INPUTS to this file, not a replacement
