Workbook

Sheet Postings
A1: FISI / Junior IT - First Job after Ausbildung
A2: Erlangen + 50 km - posted within last 14 days - generated 2026-10-12 - sources: BA Jobsuche v6, Indeed DE (JobSpy), LinkedIn guest, Arbeitnow
B4: Date | C4: Title | D4: Company | E4: City | F4: PLZ | G4: Source | H4: Salary Min | I4: Salary Max | J4: Currency | K4: Remote | L4: Junior | M4: URL | N4: Ref Nr
B5: 46307 | C5: Systemadministrator (m/w/d) | D5: OmniNet GmbH | E5: Eckental | F5: 90542 | G5: BA | M5: open | N5: 12117-YF-49468-YF-S
B6: 46307 | C6: IT Systemadministrator Microsoft 365 (m/w/d) | D6: Funkwerk Systems GmbH | E6: Nürnberg | G6: LinkedIn | M6: open
B7: 46307 | C7: IT Systemadministrator Microsoft 365 (m/w/d) | D7: HÖRMANN Gruppe | E7: Nürnberg | G7: LinkedIn | M7: open
B8: 46306 | C8: Systemadministrator (gn) im Second Level Support | D8: Papp Personal GmbH Co. KG | E8: Nürnberg | F8: 90427 | G8: BA | M8: open | N8: 14274-L4JY2HU63IRWLAXG-S
B9: 46304 | C9: Fachinformatiker Systemintegration (m/w/d) | D9: ncsolution GmbH | E9: Erlangen | G9: BA | M9: open | N9: 10001-1003832993-S
B10: 46304 | C10: Systemadministrator (m/w/d) | D10: ANG GmbH | E10: Erlangen | G10: BA | M10: open | N10: 10001-1003834249-S
B11: 46304 | C11: Junior IT- System Administrator (m/w/d) | D11: Neumüller Personalberatung Regina Neumüller e.K. | E11: Nürnberg | F11: 90425 | G11: BA | L11: yes | M11: open | N11: 10001-1003830628-S
B12: 46304 | C12: Mitarbeiter IT-Support | Administration | Projekte (m/w/d) | D12: NConsult GmbH | E12: Nürnberg | G12: BA | M12: open | N12: 10001-1003830762-S
B13: 46304 | C13: 1st Level Supporter (m/w/d) | D13: NConsult GmbH | E13: Bamberg | G13: BA | L13: yes | M13: open | N13: 10001-1003830672-S
B14: 46304 | C14: IT Specialist (m/w/d) - Clientmanagement | D14: Neumüller Personalberatung Regina Neumüller e.K. | E14: Röthenbach an der Pegnitz | F14: 90552 | G14: BA | M14: open | N14: 10001-1003831106-S
B15: 46304 | C15: IT-Systemadministrator (m/w/d) | D15: Akkodis Germany Tech Experts GmbH | E15: Nürnberg | F15: 90489 | G15: BA | M15: open | N15: 12634-BB-646012-7878-6530-S
B16: 46304 | C16: IT Systemadministrator (m/w/d) | D16: FERCHAU GmbH Niederlassung Nürnberg City | E16: Heroldsberg | F16: 90562 | G16: BA | M16: open | N16: 12265-498673_JB5268561-S
B17: 46304 | C17: IT-Consultant Telematikinfrastruktur (all genders) | D17: adesso SE | E17: Nürnberg | G17: LinkedIn | M17: open
B18: 46303 | C18: IT Support Mitarbeiter (m/w/d) Netzwerktechnik | D18: BFI Informationssysteme GmbH | E18: Nürnberg | F18: 90411 | G18: BA | M18: open | N18: 15297-0ahr6g81-S
B19: 46303 | C19: Systemadministrator (w/m/d) – Schwerpunkt Informationssicherheit | D19: BRANDAD Group AG | E19: Fürth | G19: Indeed | M19: open
B20: 46302 | C20: Systemadministrator Netzwerk & Security | D20: Suspa GmbH Betriebsstätte Altdorf | E20: Altdorf bei Nürnberg | F20: 90518 | G20: BA | M20: open | N20: 10001-1003820240-S
B21: 46302 | C21: IT-Systemadministrator (m/w/d) | D21: Brodos AG | E21: Baiersdorf | F21: 91083 | G21: BA | M21: open | N21: 10001-1003818873-S
B22: 46302 | C22: IT Support Specialist (m/w/d) Netzwerk & Linux | D22: iSK GmbH Personaldienstleistungen | E22: Erlangen | F22: 91058 | G22: BA | M22: open | N22: 12262-13890876-S
B23: 46302 | C23: IT-Systemadministrator Infrastruktur & Cloud (m/w/d), Neumarkt in der Oberpfalz | D23: PFLEIDERER Deutschland GmbH | E23: Neumarkt in der Oberpfalz | F23: 92318 | G23: BA | M23: open | N23: 12811-2352392-S
B24: 46301 | C24: IT-Service Desk Mitarbeiter (m/w/d) - Referenznummer: 061026-3-NBG | D24: BFI Informationssysteme GmbH | E24: Nürnberg | F24: 90409 | G24: BA | M24: open | N24: 15297-2u0wf5wb-S
B25: 46301 | C25: IT-Systemadministrator (m/w/d) | D25: Hegmanns AG | E25: Nürnberg | F25: 90489 | G25: BA+LinkedIn | M25: open | N25: 10001-1003811452-S
B26: 46301 | C26: Mitarbeiter (m/w/d) IT-Infrastruktur inkl. Softwareentwicklung | D26: Sill Optics GmbH | E26: Wendelstein | F26: 90530 | G26: BA | M26: open | N26: 10001-1003809182-S
B27: 46301 | C27: Systembetreuer (w/m/d) für Rechenzentrumsbetrieb | D27: Siemens | E27: Erlangen | G27: LinkedIn | M27: open
B28: 46301 | C28: IT System Administrator (all gender) | D28: ALTEN | E28: Nürnberg | G28: LinkedIn | M28: open
B29: 46300 | C29: IT-Systemadministrator:in | D29: zollsoft GmbH | E29: Sachsen bei Ansbach | F29: 91623 | G29: BA | M29: open | N29: 13635-5567d354_JB5264894-S
B30: 46299 | C30: Fachinformatiker Systemintegration (m/w/d) | D30: puro Personaldienstleistung GmbH | E30: Neumarkt in der Oberpfalz | F30: 92318 | G30: BA | M30: open | N30: 13669-B4QJPZOZC7TLDT27-S
B31: 46297 | C31: IT-Spezialist Netzwerk & Connectivity (m/w/d) | D31: FERCHAU GmbH Niederlassung Nürnberg City | E31: Erlangen | F31: 91058 | G31: BA | M31: open | N31: 12265-516301_JB5262829-S
B32: 46297 | C32: IT-Spezialist (w/m/d) | D32: Brunel GmbH NL Mannheim | E32: Erlangen | F32: 91052 | G32: BA | M32: open | N32: 12362-TR-300879_624701LS-S
B33: 46297 | C33: Mitarbeiter IT-Support / First Level Support (m/w/d) | D33: Kräuter Mix GmbH | E33: Abtswind | F33: 97355 | G33: BA | L33: yes | M33: open | N33: 12511-2026X0000052839-S
B34: 46297 | C34: IT-ServicetechnikerIn (m/w/d) Technischer Support im Innendienst | D34: PHARMATECHNIK GmbH & Co. KG | E34: Nürnberg | F34: 90403 | G34: BA | M34: open | N34: 11858-SDE-123853-STA-S
B35: 46297 | C35: (Junior) IT Manager First Level Support (m/w/d) | D35: SIMBA DICKIE GROUP GMBH | E35: Fürth | G35: Indeed | L35: yes | M35: open
B36: 46297 | C36: IT-Systemadministrator Infrastruktur & Cloud (m/w/d) | D36: PFLEIDERER | E36: Neumarkt in der Oberpfalz | G36: Indeed | M36: open
B37: 46297 | C37: IT-Spezialist:in | D37: berg-it Projektdienstleistungen GmbH | E37: Nürnberg | G37: LinkedIn | M37: open
B38: 46296 | C38: "Mein Sport? IT Support!", Supporter (m/w/d) im Help Desk | D38: Akkodis Germany Tech Experts GmbH | E38: Nürnberg | F38: 90489 | G38: BA | L38: yes | M38: open | N38: 12634-BB-645656-7878-5866-S
B39: 46296 | C39: Elektroingenieur (m/w/d) Systemintegration | D39: MCA Engineering GmbH | E39: Nürnberg | F39: 90402 | G39: BA | M39: open | N39: 14751-351A739-S
B40: 46296 | C40: IT-ServicetechnikerIn (m/w/d) Technischer Support im Innendienst | D40: Pharmatechnik KG 01 | E40: Schnaittach | F40: 91220 | G40: BA | M40: open | N40: 16265-0067825301-S
B41: 46295 | C41: Professional System Engineer / IT System Administrator Test- & Plattformbetrieb (m/w/d) | D41: Akkodis Germany Tech Experts GmbH | E41: Nürnberg | F41: 90489 | G41: BA | M41: open | N41: 12634-BB-645620-7878-4652-S
...

Sheet Summary
A1: Summary - live formulas (update if you edit the Postings sheet)
A3: By source (wildcard: multi-source rows count in each)
A4: Value | B4: Count
A5: BA | B5: =COUNTIF(Postings!$G$5:$G$49,"*BA*") -> 31
A6: Indeed | B6: =COUNTIF(Postings!$G$5:$G$49,"*Indeed*") -> 6
A7: LinkedIn | B7: =COUNTIF(Postings!$G$5:$G$49,"*LinkedIn*") -> 9
A8: TOTAL | B8: =SUM(B5:B7) -> 46
A10: By city
A11: Value | B11: Count
A12: Abtswind | B12: =COUNTIF(Postings!$E$5:$E$49,"Abtswind") -> 1
A13: Altdorf bei Nürnberg | B13: =COUNTIF(Postings!$E$5:$E$49,"Altdorf bei Nürnberg") -> 1
A14: Baiersdorf | B14: =COUNTIF(Postings!$E$5:$E$49,"Baiersdorf") -> 1
A15: Bamberg | B15: =COUNTIF(Postings!$E$5:$E$49,"Bamberg") -> 3
A16: Eckental | B16: =COUNTIF(Postings!$E$5:$E$49,"Eckental") -> 1
A17: Erlangen | B17: =COUNTIF(Postings!$E$5:$E$49,"Erlangen") -> 7
A18: Forchheim | B18: =COUNTIF(Postings!$E$5:$E$49,"Forchheim") -> 1
A19: Fürth | B19: =COUNTIF(Postings!$E$5:$E$49,"Fürth") -> 3
A20: Heroldsberg | B20: =COUNTIF(Postings!$E$5:$E$49,"Heroldsberg") -> 1
A21: Neumarkt in der Oberpfalz | B21: =COUNTIF(Postings!$E$5:$E$49,"Neumarkt in der Oberpfalz") -> 3
A22: Nürnberg | B22: =COUNTIF(Postings!$E$5:$E$49,"Nürnberg") -> 18
A23: Röthenbach an der Pegnitz | B23: =COUNTIF(Postings!$E$5:$E$49,"Röthenbach an der Pegnitz") -> 1
A24: Sachsen bei Ansbach | B24: =COUNTIF(Postings!$E$5:$E$49,"Sachsen bei Ansbach") -> 1
A25: Schnaittach | B25: =COUNTIF(Postings!$E$5:$E$49,"Schnaittach") -> 1
A26: Stein bei Nürnberg | B26: =COUNTIF(Postings!$E$5:$E$49,"Stein bei Nürnberg") -> 1
A27: Wendelstein | B27: =COUNTIF(Postings!$E$5:$E$49,"Wendelstein") -> 1
A28: TOTAL | B28: =SUM(B12:B27) -> 45
A30: By date posted
A31: Value | B31: Count
A32: 2026-10-12 | B32: =COUNTIF(Postings!$B$5:$B$49,"2026-10-12") -> 3
A33: 2026-10-11 | B33: =COUNTIF(Postings!$B$5:$B$49,"2026-10-11") -> 1
A34: 2026-10-09 | B34: =COUNTIF(Postings!$B$5:$B$49,"2026-10-09") -> 9
A35: 2026-10-08 | B35: =COUNTIF(Postings!$B$5:$B$49,"2026-10-08") -> 2
A36: 2026-10-07 | B36: =COUNTIF(Postings!$B$5:$B$49,"2026-10-07") -> 4
A37: 2026-10-06 | B37: =COUNTIF(Postings!$B$5:$B$49,"2026-10-06") -> 5
A38: 2026-10-05 | B38: =COUNTIF(Postings!$B$5:$B$49,"2026-10-05") -> 1
A39: 2026-10-04 | B39: =COUNTIF(Postings!$B$5:$B$49,"2026-10-04") -> 1
A40: 2026-10-02 | B40: =COUNTIF(Postings!$B$5:$B$49,"2026-10-02") -> 7
A41: 2026-10-01 | B41: =COUNTIF(Postings!$B$5:$B$49,"2026-10-01") -> 3
A42: 2026-09-30 | B42: =COUNTIF(Postings!$B$5:$B$49,"2026-09-30") -> 3
A43: 2026-09-28 | B43: =COUNTIF(Postings!$B$5:$B$49,"2026-09-28") -> 6
...

Sheet Review
A1: Check | B1: Expected | C1: Actual | D1: Status
A2: Posting count | B2: 45 | C2: =COUNTA(Postings!C5:C49) -> 45 | D2: =IF(B2=C2,"PASS","FAIL") -> PASS
A3: Junior-signal rows | B3: 5 | C3: =COUNTIF(Postings!L5:L49,"yes") -> 5 | D3: =IF(B3=C3,"PASS","FAIL") -> PASS
A4: Oldest posting within 14 days | B4: TRUE | C4: =MIN(Postings!B5:B49)>=DATE(YEAR(TODAY()),MONTH(TODAY()-14),DAY(TODAY()-14)) -> TRUE | D4: =IF(C4=TRUE(),"PASS","FAIL") -> PASS
